<?xml version="1.0"?>

<robot xmlns:xacro="http://www.ros.org/wiki/xacro">

    <xacro:include filename="$(find kuka_resources)/urdf/common_materials.xacro"/>

    <xacro:property name="DEG2RAD" value="0.017453292519943295"/>
    <xacro:property name="PI" value="3.141592653589793"/>

    <xacro:macro name="kuka_kr5arc" params="prefix">

        <!-- LINKS -->
        <!-- base link -->
        <link name="${prefix}base_link">
            <visual>
                <origin xyz="0 0 0" rpy="0 0 0"/>
                <geometry>
                    <mesh filename="package://kuka_kr5_support/meshes/kr5arc/visual/base_link.stl" scale="0.001 0.001 0.001" />
                </geometry>
                <xacro:material_kuka_black/>
            </visual>
            <collision>
                <origin xyz="0 0 0" rpy="0 0 0"/>
                <geometry>
                    <mesh filename="package://kuka_kr5_support/meshes/kr5arc/collision/base_link.stl" scale="0.001 0.001 0.001" />
                </geometry>
            </collision>
        </link>
        <!-- link 1 -->
        <link name="${prefix}link_1">
            <!-- main link body -->
            <visual>
                <origin xyz="0 0 -0.2245" rpy="0 0 0"/>
                <geometry>
                    <mesh filename="package://kuka_kr5_support/meshes/kr5arc/visual/link_1.stl" scale="0.001 0.001 0.001" />
                </geometry>
                <xacro:material_kuka_orange/>
            </visual>
            <collision>
                <origin xyz="0 0 -0.2245" rpy="0 0 0"/>
                <geometry>
                    <mesh filename="package://kuka_kr5_support/meshes/kr5arc/collision/link_1.stl" scale="0.001 0.001 0.001" />
                </geometry>
            </collision>
        </link>
        <!-- link 2 -->
        <link name="${prefix}link_2">
            <visual>
                <origin xyz="-0.18 0 -0.4" rpy="0 0 0"/>
                <geometry>
                    <mesh filename="package://kuka_kr5_support/meshes/kr5arc/visual/link_2.stl" scale="0.001 0.001 0.001" />
                </geometry>
                <xacro:material_kuka_orange/>
            </visual>
            <collision>
                <origin xyz="-0.18 0 -0.4" rpy="0 0 0"/>
                <geometry>
                    <mesh filename="package://kuka_kr5_support/meshes/kr5arc/collision/link_2.stl" scale="0.001 0.001 0.001" />
                </geometry>
            </collision>
        </link>
        <!-- link 3 -->
        <link name="${prefix}link_3">
            <visual>
                <origin xyz="-0.18 0 -1.0" rpy="0 0 0"/>
                <geometry>
                    <mesh filename="package://kuka_kr5_support/meshes/kr5arc/visual/link_3.stl" scale="0.001 0.001 0.001" />
                </geometry>
                <xacro:material_kuka_orange/>
            </visual>
            <collision>
                <origin xyz="-0.18 0 -1.0" rpy="0 0 0"/>
                <geometry>
                    <mesh filename="package://kuka_kr5_support/meshes/kr5arc/collision/link_3.stl" scale="0.001 0.001 0.001" />
                </geometry>
            </collision>
        </link>
        <!-- link 4 -->
        <link name="${prefix}link_4">
            <visual>
                <origin xyz="-0.5835 0 -1.120" rpy="0 0 0"/>
                <geometry>
                    <mesh filename="package://kuka_kr5_support/meshes/kr5arc/visual/link_4.stl" scale="0.001 0.001 0.001" />
                </geometry>
                <xacro:material_kuka_orange/>
            </visual>
            <collision>
                <origin xyz="-0.5835 0 -1.120" rpy="0 0 0"/>
                <geometry>
                    <mesh filename="package://kuka_kr5_support/meshes/kr5arc/collision/link_4.stl" scale="0.001 0.001 0.001" />
                </geometry>
            </collision>
        </link>
        <!-- link 5 -->
        <link name="${prefix}link_5">
            <visual>
                <origin xyz="-0.8 0 -1.120" rpy="0 0 0"/>
                <geometry>
                    <mesh filename="package://kuka_kr5_support/meshes/kr5arc/visual/link_5.stl" scale="0.001 0.001 0.001" />
                </geometry>
                <xacro:material_kuka_orange/>
            </visual>
            <collision>
                <origin xyz="-0.8 0 -1.120" rpy="0 0 0"/>
                <geometry>
                    <mesh filename="package://kuka_kr5_support/meshes/kr5arc/collision/link_5.stl" scale="0.001 0.001 0.001" />
                </geometry>
            </collision>
        </link>
        <!-- link 6 -->
        <link name="${prefix}link_6">
            <visual>
                <origin xyz="-0.9088 0 -1.120" rpy="0 0 0"/>
                <geometry>
                    <mesh filename="package://kuka_kr5_support/meshes/kr5arc/visual/link_6.stl" scale="0.001 0.001 0.001" />
                </geometry>
                <xacro:material_kuka_black/>
            </visual>
            <collision>
                <origin xyz="-0.9088 0 -1.120" rpy="0 0 0"/>
                <geometry>
                    <mesh filename="package://kuka_kr5_support/meshes/kr5arc/collision/link_6.stl" scale="0.001 0.001 0.001" />
                </geometry>
            </collision>
        </link>
        <!-- tool 0 -->
        <link name="${prefix}tool0"/>
        <!-- END LINKS -->

        <!-- JOINTS -->
        <!-- joint 1 (A1) -->
        <joint name="${prefix}joint_1" type="revolute">
            <origin xyz="0 0 0.2245" rpy="0 0 0"/>
            <parent link="${prefix}base_link"/>
            <child link="${prefix}link_1"/>
            <axis xyz="0 0 -1"/>
            <limit effort="0" lower="${-DEG2RAD * 155}" upper="${DEG2RAD * 155}" velocity="${DEG2RAD * 154}"/>
        </joint>

        <!-- joint 2 (A2) -->
        <joint name="${prefix}joint_2" type="revolute">
            <origin xyz="0.18 0 ${0.4-0.2245}" rpy="0 ${PI/2} 0"/>
            <parent link="${prefix}link_1"/>
            <child link="${prefix}link_2"/>
            <axis xyz="0 1 0"/>
            <limit effort="0" lower="${-DEG2RAD * 180}" upper="${DEG2RAD * 65}" velocity="${DEG2RAD * 154}"/>
        </joint>

        <!-- joint 3 (A3) -->
        <joint name="${prefix}joint_3" type="revolute">
            <origin xyz="0 0 0.6" rpy="0 ${-PI/2} 0"/>
            <parent link="${prefix}link_2"/>
            <child link="${prefix}link_3"/>
            <axis xyz="0 1 0"/>
            <limit effort="0" lower="${-DEG2RAD * 15}" upper="${DEG2RAD * 158}" velocity="${DEG2RAD * 228}"/>
        </joint>

        <!-- joint 4 (A4) -->
        <joint name="${prefix}joint_4" type="revolute">
            <origin xyz="${0.5835-0.18} 0 0.12" rpy="0 0 0"/>
            <parent link="${prefix}link_3"/>
            <child link="${prefix}link_4"/>
            <axis xyz="-1 0 0"/>
            <limit effort="0" lower="${-DEG2RAD * 350}" upper="${DEG2RAD * 350}" velocity="${DEG2RAD * 343}"/>
        </joint>

        <!-- joint 5 (A5) -->
        <joint name="${prefix}joint_5" type="revolute">
            <origin xyz="${0.80-0.5835} 0 0" rpy="0 0 0"/>
            <parent link="${prefix}link_4"/>
            <child link="${prefix}link_5"/>
            <axis xyz="0 1 0"/>
            <limit effort="0" lower="${-DEG2RAD * 130}" upper="${DEG2RAD * 130}" velocity="${DEG2RAD * 384}"/>
        </joint>

        <!-- joint 6 (A6) -->
        <joint name="${prefix}joint_6" type="revolute">
            <origin xyz="${0.915-0.80} 0 0" rpy="0 0 0"/>
            <parent link="${prefix}link_5"/>
            <child link="${prefix}link_6"/>
            <axis xyz="-1 0 0"/>
            <limit effort="0" lower="${-DEG2RAD * 350}" upper="${DEG2RAD * 350}" velocity="${DEG2RAD * 721}"/>
        </joint>

        <joint name="${prefix}joint_6-tool0" type="fixed">
            <parent link="${prefix}link_6"/>
            <child link="${prefix}tool0"/>
            <origin xyz="0 0 0" rpy="0 ${PI/2} 0"/>
        </joint>
        <!-- END JOINTS -->

        <!-- MOTORS -->
        <!-- A1 motor -->
        <link name="${prefix}link_1_motor1">
            <!-- motor 1 -->
            <visual>
                <origin xyz="0 0 -0.2245" rpy="0 0 0"/>
                <geometry>
                    <mesh filename="package://kuka_kr5_support/meshes/kr5arc/visual/link_1_motor1.stl" scale="0.001 0.001 0.001" />
                </geometry>
                <xacro:material_kuka_black/>
            </visual>
            <collision>
                <origin xyz="0 0 -0.2245" rpy="0 0 0"/>
                <geometry>
                    <mesh filename="package://kuka_kr5_support/meshes/kr5arc/collision/link_1_motor1.stl" scale="0.001 0.001 0.001" />
                </geometry>
            </collision>
        </link>
        <!-- A2 motor -->
        <link name="${prefix}link_1_motor2">
            <!-- motor 1 -->
            <visual>
                <origin xyz="0 0 -0.2245" rpy="0 0 0"/>
                <geometry>
                    <mesh filename="package://kuka_kr5_support/meshes/kr5arc/visual/link_1_motor2.stl" scale="0.001 0.001 0.001" />
                </geometry>
                <xacro:material_kuka_black/>
            </visual>
            <collision>
                <origin xyz="0 0 -0.2245" rpy="0 0 0"/>
                <geometry>
                    <mesh filename="package://kuka_kr5_support/meshes/kr5arc/collision/link_1_motor2.stl" scale="0.001 0.001 0.001" />
                </geometry>
            </collision>
        </link>
        <!-- A4 motor -->
        <link name="${prefix}link_3_motor1">
            <visual>
                <origin xyz="-0.18 0 -1.0" rpy="0 0 0"/>
                <geometry>
                    <mesh filename="package://kuka_kr5_support/meshes/kr5arc/visual/link_3_motor1.stl" scale="0.001 0.001 0.001" />
                </geometry>
                <xacro:material_kuka_black/>
            </visual>
            <collision>
                <origin xyz="-0.18 0 -1.0" rpy="0 0 0"/>
                <geometry>
                    <mesh filename="package://kuka_kr5_support/meshes/kr5arc/collision/link_3_motor1.stl" scale="0.001 0.001 0.001" />
                </geometry>
            </collision>
        </link>
        <!-- A5 motor -->
        <link name="${prefix}link_3_motor2">
            <visual>
                <origin xyz="-0.18 0 -1.0" rpy="0 0 0"/>
                <geometry>
                    <mesh filename="package://kuka_kr5_support/meshes/kr5arc/visual/link_3_motor2.stl" scale="0.001 0.001 0.001" />
                </geometry>
                <xacro:material_kuka_black/>
            </visual>
            <collision>
                <origin xyz="-0.18 0 -1.0" rpy="0 0 0"/>
                <geometry>
                    <mesh filename="package://kuka_kr5_support/meshes/kr5arc/collision/link_3_motor2.stl" scale="0.001 0.001 0.001" />
                </geometry>
            </collision>
        </link>
        <!-- A6 motor -->
        <link name="${prefix}link_3_motor3">
            <visual>
                <origin xyz="-0.18 0 -1.0" rpy="0 0 0"/>
                <geometry>
                    <mesh filename="package://kuka_kr5_support/meshes/kr5arc/visual/link_3_motor3.stl" scale="0.001 0.001 0.001" />
                </geometry>
                <xacro:material_kuka_black/>
            </visual>
            <collision>
                <origin xyz="-0.18 0 -1.0" rpy="0 0 0"/>
                <geometry>
                    <mesh filename="package://kuka_kr5_support/meshes/kr5arc/collision/link_3_motor3.stl" scale="0.001 0.001 0.001" />
                </geometry>
            </collision>
        </link>
        <!-- A3 motor -->
        <link name="${prefix}link_3_motor4">
            <visual>
                <origin xyz="-0.18 0 -1.0" rpy="0 0 0"/>
                <geometry>
                    <mesh filename="package://kuka_kr5_support/meshes/kr5arc/visual/link_3_motor4.stl" scale="0.001 0.001 0.001" />
                </geometry>
                <xacro:material_kuka_black/>
            </visual>
            <collision>
                <origin xyz="-0.18 0 -0.4" rpy="0 0 0"/>
                <geometry>
                    <mesh filename="package://kuka_kr5_support/meshes/kr5arc/collision/link_3_motor4.stl" scale="0.001 0.001 0.001" />
                </geometry>
            </collision>
        </link>

        <!-- dummy motor joint -->
        <joint name="${prefix}joint_1_motor1" type="fixed">
            <origin xyz="0 0 0" rpy="0 0 0"/>
            <parent link="${prefix}link_1"/>
            <child link="${prefix}link_1_motor1"/>
        </joint>
        <!-- dummy motor joint -->
        <joint name="${prefix}joint_1_motor2" type="fixed">
            <origin xyz="0 0 0" rpy="0 0 0"/>
            <parent link="${prefix}link_1"/>
            <child link="${prefix}link_1_motor2"/>
        </joint>
        <!-- dummy  motor joint -->
        <joint name="${prefix}joint_3_motor1" type="fixed">
            <origin xyz="0 0 0" rpy="0 0 0"/>
            <parent link="${prefix}link_3"/>
            <child link="${prefix}link_3_motor1"/>
        </joint>
        <!-- dummy  motor joint -->
        <joint name="${prefix}joint_3_motor2" type="fixed">
            <origin xyz="0 0 0" rpy="0 0 0"/>
            <parent link="${prefix}link_3"/>
            <child link="${prefix}link_3_motor2"/>
        </joint>
        <!-- dummy  motor joint -->
        <joint name="${prefix}joint_3_motor3" type="fixed">
            <origin xyz="0 0 0" rpy="0 0 0"/>
            <parent link="${prefix}link_3"/>
            <child link="${prefix}link_3_motor3"/>
        </joint>
        <!-- dummy motor joint -->
        <joint name="${prefix}joint_3_motor4" type="fixed">
            <origin xyz="0 0 0" rpy="0 0 0"/>
            <parent link="${prefix}link_3"/>
            <child link="${prefix}link_3_motor4"/>
        </joint>
        <!-- END MOTORS -->

    </xacro:macro>
</robot>


